Workbook

Sheet RESUMEN SUPERFICIES
O4: VERSION 25
C5: DUNAMAR | O5: P.E.
O6: 43752
C8: FICHA ARQUITECTONICA
C10: COMUNA: | D10: CONCON
C12: CERTIFICADO DE INFORMES PREVIOS N° | F12: 3032/3033 | H12: PLANO REFERENCIA: | J12: 07. DESARROLLO\01. ARQUITECTURA\01. A0\100-V25-DUNAMAR PLANTAS-14-10-19.dwg
C14: CONDICIONES DE EDIFICACION
C16: Zona de Edificacion | E16: ZVCM-H7 | I16: DISTANCIAMIENTOS | M16: NOTAS:
C17: Rasante | E17: 70° | I17: Antejardin | K17: 5 | M17: 1, LA CABIDA SE HACE CON INFORMES PREVIOS
I18: Dist. Medianeros | K18: 4
C19: Densidad Maxima | E19: 980 | F19: Hab/ha | I19: Dist. Antejardin Subterraneo | K19: 5 | M19: 2, LA CABIDA SE HACE CON PLANO TOPOGRAFICO
I20: Dist. Medianeros Subterraneo | K20: 1
C21: Maximo Ocupacion de suelo | E21: 0.3
C22: Maximo Ocupacion de Pisos Superiores | E22: 0 | I22: PROPUESTA
C23: Superficie Predial Minima | E23: 1000 | I23: N° de Pisos | K23: 22
C24: Constructibilidad | E24: 2 | I24: Altura piso 1° | K24: 2.52
C25: Premio Fusion o C.A. (30% - 50%) | D25: 0.3 | E25: =E24*D25 -> 0.6 | I25: Altura piso tipo | K25: 2.52
C26: TOTAL | E26: =SUM(E24:E25) -> 2.6 | I26: Altura Subterraneo 1 | K26: 2.88
I27: Altura Subterraneo 2
C28: Altura max (pisos) | E28: 20 | I28: Altura Subterraneo 3 | K28: -
C29: Premio 25% C.A. | D29: 0 | E29: =E28*D29 -> 0 | I29: Altura npt 1° Nivel acceso | K29: 0.15
C30: Piso Recogido | E30: 0 | I30: Altura total Edificio | K30: =K25*K23 -> 55.44
C31: TOTAL | E31: =SUM(E28:E30) -> 20 | I31: Altura a enterrarse | K31: 1.44
I32: Altura total sobre N.T.N. | K32: =K30-K31+1 -> 55
C33: Superficie terreno | E33: 5312 | F33: m2
C34: Area Afecta a Utilidad Publica | E34: 0 | F34: m2
C35: Superficie Neta | E35: =E33-E34 -> 5312 | F35: m2
C36: Constructibilidad max permitida | E36: =E35*E26 -> 13811.2 | F36: m2
C37: Superficie Media Calzada | E37: =664.24+1992.78 -> 2657.02 | F37: m2
C38: Superficie para Densidad | E38: =E35+E37 -> 7969.02 | F38: m2
C39: Numero de vivendas permitidas | E39: =((E19*E38)/10000)/4 -> 195.24099 | F39: un
C40: Media departamentos | E40: =E36/E39 -> 70.739244 | F40: m2
C45: CUADROS DE SUPERFICIES EDIFICIO VIVIENDA
C48: PISOS | D48: Superficie Municipal x Recinto
D49: Int Dpto | E49: Loggia | F49: Bodegas y Est. Mun. | G49: Total Util | H49: Subterraneos | I49: Terraza | J49: Area | K49: Total Comun | L49: TOTAL
D50: Municipal | E50: Municipal | I50: Municipal | J50: Comun | K50: Municipal
D51: m2 | E51: m2 | F51: m2 | G51: m2 | H51: m2 | I51: m2 | J51: m2 | K51: m2 | L51: m2
C52: Subterraneo 3 | D52: =D93 -> 500.13 | G52: =SUM(D52:F52) -> 500.13 | H52: =I93+G93+H93 -> 1000.26 | L52: =G52+H52 -> 1500.39
C53: Subterraneo 2 | G53: =SUM(D53:F53) -> 0 | H53: =I94+G94 -> 2255.63 | L53: =+G53+H53+K53 -> 2255.63
C54: Subterraneo 1 | G54: =SUM(D54:F54) -> 0 | H54: =I95+G95 -> 2211.41 | L54: =+G54+H54+K54 -> 2211.41
...

Sheet SUP. DEPARTAMENTOS
B2: ='RESUMEN SUPERFICIES'!C5 -> DUNAMAR | G2: ='RESUMEN SUPERFICIES'!O5 -> P.E.
G3: ='RESUMEN SUPERFICIES'!O6 -> 43752
B6: SUPERFICIES DE LOSAS DEPARTAMENTOS
B7: PISO | C7: N° DEPTO | D7: M2 INTERIOR | E7: M2 TERRAZA BALCON | F7: M2 TERRAZA TECHO | G7: M2 TOTAL
B8: 2 | C8: 204 | D8: =D16 -> 50.18 | F8: =F16 -> 8.99 | G8: =SUM(D8:F8) -> 59.17
B9: 2 | C9: 205 | D9: =D17 -> 57.67 | F9: =F17 -> 8.21 | G9: =SUM(D9:F9) -> 65.88
B10: 2 | C10: 207 | D10: =D19 -> 50.18 | F10: =F19 -> 8.99 | G10: =SUM(D10:F10) -> 59.17
B11: 2 | C11: 208 | D11: =D20 -> 60.68 | F11: =F20 -> 9.32 | G11: =SUM(D11:F11) -> 70
B12: 2 | C12: 209 | D12: =D21 -> 50.28 | F12: =F21 -> 8.99 | G12: =SUM(D12:F12) -> 59.27
B13: 3 | C13: 301 | D13: ='RESUMEN SUPERFICIES'!K157 -> 33.24 | F13: ='RESUMEN SUPERFICIES'!M157 -> 7.98 | G13: =SUM(D13:F13) -> 41.22
B14: 3 | C14: 302 | D14: ='RESUMEN SUPERFICIES'!K159 -> 50.18 | F14: ='RESUMEN SUPERFICIES'!M159 -> 8.99 | G14: =SUM(D14:F14) -> 59.17
B15: 3 | C15: 303 | D15: ='RESUMEN SUPERFICIES'!K162 -> 71.18 | F15: ='RESUMEN SUPERFICIES'!M161 -> 8.21 | G15: =SUM(D15:F15) -> 79.39
B16: 3 | C16: 304 | D16: ='RESUMEN SUPERFICIES'!K158 -> 50.18 | F16: ='RESUMEN SUPERFICIES'!M158 -> 8.99 | G16: =SUM(D16:F16) -> 59.17
B17: 3 | C17: 305 | D17: ='RESUMEN SUPERFICIES'!K161 -> 57.67 | F17: ='RESUMEN SUPERFICIES'!M161 -> 8.21 | G17: =SUM(D17:F17) -> 65.88
B18: 3 | C18: 306 | D18: ='RESUMEN SUPERFICIES'!K161 -> 57.67 | F18: ='RESUMEN SUPERFICIES'!M161 -> 8.21 | G18: =SUM(D18:F18) -> 65.88
B19: 3 | C19: 307 | D19: ='RESUMEN SUPERFICIES'!K158 -> 50.18 | F19: ='RESUMEN SUPERFICIES'!M158 -> 8.99 | G19: =SUM(D19:F19) -> 59.17
B20: 3 | C20: 308 | D20: ='RESUMEN SUPERFICIES'!K163 -> 60.68 | F20: ='RESUMEN SUPERFICIES'!M163 -> 9.32 | G20: =SUM(D20:F20) -> 70
B21: 3 | C21: 309 | D21: ='RESUMEN SUPERFICIES'!K160 -> 50.28 | F21: ='RESUMEN SUPERFICIES'!M160 -> 8.99 | G21: =SUM(D21:F21) -> 59.27
B22: 3 | C22: 310 | D22: ='RESUMEN SUPERFICIES'!K157 -> 33.24 | F22: ='RESUMEN SUPERFICIES'!M157 -> 7.98 | G22: =SUM(D22:F22) -> 41.22
B23: 4 | C23: 401 | D23: =D13 -> 33.24 | F23: =F13 -> 7.98 | G23: =SUM(D23:F23) -> 41.22
B24: 4 | C24: 402 | D24: =D14 -> 50.18 | F24: =F14 -> 8.99 | G24: =SUM(D24:F24) -> 59.17
B25: 4 | C25: 403 | D25: =D15 -> 71.18 | F25: =F15 -> 8.21 | G25: =SUM(D25:F25) -> 79.39
B26: 4 | C26: 404 | D26: =D16 -> 50.18 | F26: =F16 -> 8.99 | G26: =SUM(D26:F26) -> 59.17
B27: 4 | C27: 405 | D27: =D17 -> 57.67 | F27: =F17 -> 8.21 | G27: =SUM(D27:F27) -> 65.88
B28: 4 | C28: 406 | D28: =D18 -> 57.67 | F28: =F18 -> 8.21 | G28: =SUM(D28:F28) -> 65.88
B29: 4 | C29: 407 | D29: =D19 -> 50.18 | F29: =F19 -> 8.99 | G29: =SUM(D29:F29) -> 59.17
B30: 4 | C30: 408 | D30: =D20 -> 60.68 | F30: =F20 -> 9.32 | G30: =SUM(D30:F30) -> 70
B31: 4 | C31: 409 | D31: =D21 -> 50.28 | F31: =F21 -> 8.99 | G31: =SUM(D31:F31) -> 59.27
B32: 4 | C32: 410 | D32: =D22 -> 33.24 | F32: =F22 -> 7.98 | G32: =SUM(D32:F32) -> 41.22
B33: 5 | C33: 501 | D33: =D23 -> 33.24 | F33: =F23 -> 7.98 | G33: =SUM(D33:F33) -> 41.22
B34: 5 | C34: 502 | D34: =D24 -> 50.18 | F34: =F24 -> 8.99 | G34: =SUM(D34:F34) -> 59.17
... B182: 19 | C182: 1910 | D182: =D172 -> 33.24 | F182: =F172 -> 7.98 | G182: =SUM(D182:F182) -> 41.22
B183: 20 | C183: 2001 | D183: 33.4 | F183: 9.06 | G183: =SUM(D183:F183) -> 42.46
B184: 20 | C184: 2002 | D184: 50.17 | F184: 13.36 | G184: =SUM(D184:F184) -> 63.53
B185: 20 | C185: 2003 | D185: 72.82 | F185: 15.03 | G185: =SUM(D185:F185) -> 87.85
B186: 20 | C186: 2004 | D186: 50.41 | F186: 13.2 | G186: =SUM(D186:F186) -> 63.61
B187: 20 | C187: 2005 | D187: 57.74 | F187: 16.54 | G187: =SUM(D187:F187) -> 74.28
B188: 20 | C188: 2006 | D188: 57.74 | F188: 16.54 | G188: =SUM(D188:F188) -> 74.28
B189: 20 | C189: 2007 | D189: 50.41 | F189: 13.2 | G189: =SUM(D189:F189) -> 63.61
B190: 20 | C190: 2008 | D190: 72.82 | F190: 15.03 | G190: =SUM(D190:F190) -> 87.85
...

Sheet PRODUCTOS SECUNDARIOS
B2: ='RESUMEN SUPERFICIES'!C5 -> DUNAMAR | N2: ='RESUMEN SUPERFICIES'!O5 -> P.E.
N3: ='RESUMEN SUPERFICIES'!O6 -> 43752
B5: BODEGAS INDIVIDUALES | F5: ESTACIONAMIENTOS INDIVIDUALES | K5: VENTA EN CONJUNTO
B6: PISO | C6: N° BODEGA | D6: M2 UTIL MUNICIPAL | F6: PISO | G6: N° ESTACIONAMIENTO | H6: SUPERFICIE | I6: USO | K6: PISO | L6: N° ESTACIONAMIENTO | M6: SUPERFICIE | N6: USO | S6: PISO 2
B7: 2 | C7: B-301 | D7: 3.58 | F7: 1 | G7: EV-01 | H7: 18 | I7: USO Y GOCE EXCLUSIVO | K7: 1 | L7: B-001 | M7: 4.87 | N7: BODEGA | P7: TOTAL BODEGAS P2 | R7: =SUM(D7:D31) -> 82.76
B8: 2 | C8: B-302 | D8: =3.44-0.32 -> 3.12 | F8: 1 | G8: EV-02 | H8: 12.5 | I8: USO Y GOCE EXCLUSIVO | L8: E-25 | M8: 14.81 | N8: ESTACIONAMIENTO
B9: 2 | C9: B-303 | D9: 2.73 | F9: 1 | G9: EV-03 | H9: 12.5 | I9: USO Y GOCE EXCLUSIVO | K9: 1 | L9: B-003 | M9: =3.88-0.33 -> 3.55 | N9: BODEGA | S9: PISO 1
B10: 2 | C10: B-304 | D10: 3.96 | F10: 1 | G10: EV-04 | H10: 12.5 | I10: USO Y GOCE EXCLUSIVO | L10: E-27 | M10: 13.74 | N10: ESTACIONAMIENTO | P10: TOTAL BOD P1 INDV | R10: =SUM(D32:D33) -> 10.35
B11: 2 | C11: B-305 | D11: 3.89 | F11: 1 | G11: EV-05 | H11: 12.5 | I11: USO Y GOCE EXCLUSIVO | K11: 1 | L11: B-004 | M11: 3.65 | N11: BODEGA | P11: TOTAL BOD P1 CONJ | R11: =M7+M9+M11+M13+M15+M17+M19+M21+M23+M25+M27+M29+M31+M33+M35+M37+M39+M41 -> 74.54
B12: 2 | C12: B-306 | D12: 3.31 | F12: 1 | G12: EV-06 | H12: 12.5 | I12: USO Y GOCE EXCLUSIVO | L12: E-28 | M12: 14.21 | N12: ESTACIONAMIENTO
B13: 2 | C13: B-307 | D13: 3.13 | F13: 1 | G13: EV-07 | H13: 12.5 | I13: USO Y GOCE EXCLUSIVO | K13: 1 | L13: B-005 | M13: =3.87-0.34 -> 3.53 | N13: BODEGA | P13: TOTAL BODEGAS P1 | R13: =SUM(R10:R11) -> 84.89
B14: 2 | C14: B-308 | D14: 3.13 | F14: 1 | G14: EV-08 | H14: 12.5 | I14: USO Y GOCE EXCLUSIVO | L14: E-29 | M14: 14.05 | N14: ESTACIONAMIENTO
B15: 2 | C15: B-309 | D15: 3.28 | F15: 1 | G15: EV-09 | H15: 12.5 | I15: USO Y GOCE EXCLUSIVO | K15: 1 | L15: B-006 | M15: =3.89-0.07 -> 3.82 | N15: BODEGA | P15: TOTAL EST P1 INDV | R15: =SUM(H46:H78) -> 442.96
B16: 2 | C16: B-310 | D16: 3.6 | F16: 1 | G16: EV-10 | H16: 12.5 | I16: USO Y GOCE EXCLUSIVO | L16: E-30 | M16: 12.64 | N16: ESTACIONAMIENTO | P16: TOTAL EST P1 CONJ | R16: =M8+M10+M12+M14+M16+M18+M20+M22+M24+M26+M28+M30+M32+M34+M36+M38+M40+M42 -> 250.98
B17: 2 | C17: B-311 | D17: =3.39-0.34 -> 3.05 | F17: 1 | G17: EV-11 | H17: 12.5 | I17: USO Y GOCE EXCLUSIVO | K17: 1 | L17: B-007 | M17: =3.38-0.31 -> 3.07 | N17: BODEGA
B18: 2 | C18: B-312 | D18: =3.8-0.07 -> 3.73 | F18: 1 | G18: EV-12 | H18: 12.5 | I18: USO Y GOCE EXCLUSIVO | L18: E-31 | M18: =15.58-0.19 -> 15.39 | N18: ESTACIONAMIENTO | P18: TOTAL EST P1 | R18: =SUM(R15:R16) -> 693.94
B19: 2 | C19: B-313 | D19: 3.19 | F19: 1 | G19: EV-13 | H19: 12.5 | I19: USO Y GOCE EXCLUSIVO | K19: 1 | L19: B-008 | M19: =3.38-0.31 -> 3.07 | N19: BODEGA
B20: 2 | C20: B-314 | D20: 3.08 | F20: 1 | G20: EV-14 | H20: 12.5 | I20: USO Y GOCE EXCLUSIVO | L20: E-32 | M20: =15.58-0.19 -> 15.39 | N20: ESTACIONAMIENTO | S20: SUBTE. -1
B21: 2 | C21: B-315 | D21: 3.08 | F21: 1 | G21: EV-15 | H21: 12.5 | I21: USO Y GOCE EXCLUSIVO | K21: 1 | L21: B-009 | M21: =3.89-0.07 -> 3.82 | N21: BODEGA | P21: TOTAL BOD SUB1 INDV | R21: =SUM(D34:D35) -> 7.81
B22: 2 | C22: B-316 | D22: 3.22 | F22: 1 | G22: EV-16 | H22: 12.5 | I22: USO Y GOCE EXCLUSIVO | L22: E-33 | M22: 12.64 | N22: ESTACIONAMIENTO | P22: TOTAL BOD SUB1 CONJ | R22: =M43+M45+M47+M49+M51+M53+M55+M57+M59+M61+M63+M65+M67+M69+M71+M73+M75+M77+M79+M81+M83+M85+M87+M89 -> 116.67
B23: 2 | C23: B-317 | D23: =3.51-0.09 -> 3.42 | F23: 1 | G23: EV-17 | H23: 12.5 | I23: USO Y GOCE EXCLUSIVO | K23: 1 | L23: B-010 | M23: =3.87-0.34 -> 3.53 | N23: BODEGA
B24: 2 | C24: B-318 | D24: =3.55-0.28 -> 3.27 | F24: 1 | G24: EV-18 | H24: 12.5 | I24: USO Y GOCE EXCLUSIVO | L24: E-34 | M24: 14.05 | N24: ESTACIONAMIENTO | P24: TOTAL BODEGAS SUB1 | R24: =SUM(R21:R22) -> 124.48
B25: 2 | C25: B-319 | D25: =3.55-0.28 -> 3.27 | F25: 1 | G25: EV-19 | H25: 12.5 | I25: USO Y GOCE EXCLUSIVO | K25: 1 | L25: B-011 | M25: 3.65 | N25: BODEGA
B26: 2 | C26: B-320 | D26: =3.51-0.09 -> 3.42 | F26: 1 | G26: EV-20 | H26: 12.5 | I26: USO Y GOCE EXCLUSIVO | L26: E-35 | M26: 14.21 | N26: ESTACIONAMIENTO | P26: TOTAL EST SUB1 INDV | R26: =SUM(H79:H125) -> 588.62
B27: 2 | C27: B-321 | D27: 3.22 | F27: 1 | G27: EV-21 | H27: 12.5 | I27: USO Y GOCE EXCLUSIVO | K27: 1 | L27: B-012 | M27: =3.88-0.33 -> 3.55 | N27: BODEGA | P27: TOTAL EST SUB1 CONJ | R27: =M44+M46+M48+M50+M52+M54+M56+M58+M60+M62+M64+M66+M68+M70+M72+M74+M76+M78+M80+M82+M84+M86+M88+M90 -> 334.28
B28: 2 | C28: B-322 | D28: 3.08 | F28: 1 | G28: EV-22 | H28: 12.5 | I28: USO Y GOCE EXCLUSIVO | L28: E-36 | M28: 13.74 | N28: ESTACIONAMIENTO
B29: 2 | C29: B-323 | D29: 3.08 | F29: 1 | G29: EV-23 | H29: 12.5 | I29: USO Y GOCE EXCLUSIVO | K29: 1 | L29: B-013 | M29: 4.79 | N29: BODEGA | P29: TOTAL EST SUB1 | R29: =SUM(R26:R27) -> 922.9
B30: 2 | C30: B-324 | D30: 3.19 | F30: 1 | G30: EV-24 | H30: 12.5 | I30: USO Y GOCE EXCLUSIVO | L30: E-39 | M30: 14.55 | N30: ESTACIONAMIENTO
B31: 2 | C31: B-325 | D31: =3.8-0.07 -> 3.73 | F31: 1 | G31: EV-25 | H31: 12.5 | I31: USO Y GOCE EXCLUSIVO | K31: 1 | L31: B-015 | M31: =5.08-0.21 -> 4.87 | N31: BODEGA | S31: SUBTE. -2
B32: 1 | C32: B-002 | D32: 5.21 | F32: 1 | G32: EV-26 | H32: 12.5 | I32: USO Y GOCE EXCLUSIVO | L32: E-42 | M32: 13.65 | N32: ESTACIONAMIENTO | P32: TOTAL BOD SUB2 INDV | R32: =SUM(D36:D37) -> 12.06
B33: 1 | C33: B-014 | D33: 5.14 | F33: 1 | G33: EV-27 | H33: 12.5 | I33: USO Y GOCE EXCLUSIVO | K33: 1 | L33: B-016 | M33: 4.88 | N33: BODEGA | P33: TOTAL BOD SUB2 CONJ | R33: =M91+M93+M95+M97+M99+M101+M103+M105+M107+M109+M111+M113+M115+M117+M119+M121+M123+M125+M127+M129+M131+M133+M135+M137+M139+M141+M143 -> 134.29
B34: -1 | C34: B-102 | D34: 3.82 | F34: 1 | G34: EV-28 | H34: 12.5 | I34: USO Y GOCE EXCLUSIVO | L34: E-43 | M34: 14.15 | N34: ESTACIONAMIENTO
B35: -1 | C35: B-116 | D35: 3.99 | F35: 1 | G35: EV-29 | H35: 12.5 | I35: USO Y GOCE EXCLUSIVO | K35: 1 | L35: B-017 | M35: =5.22-0.33 -> 4.89 | N35: BODEGA | P35: TOTAL BODEGAS SUB2 | R35: =SUM(R32:R33) -> 146.35
B36: -2 | C36: B-202 | D36: 6.98 | F36: 1 | G36: EV-30 | H36: 12.5 | I36: USO Y GOCE EXCLUSIVO | L36: E-44 | M36: 14 | N36: ESTACIONAMIENTO
B37: -2 | C37: B-229 | D37: 5.08 | F37: 1 | G37: EV-31 | H37: 12.5 | I37: USO Y GOCE EXCLUSIVO | K37: 1 | L37: B-018 | M37: 5.97 | N37: BODEGA | P37: TOTAL EST SUB2 INDV | R37: =SUM(H126:H174) -> 613.62
B38: -3 | C38: BC-01 | D38: 7.7 | F38: 1 | G38: EV-32 | H38: 12.5 | I38: USO Y GOCE EXCLUSIVO | L38: E-45 | M38: 12.67 | N38: ESTACIONAMIENTO | P38: TOTAL EST SUB2 CONJ | R38: =M92+M94+M96+M98+M100+M102+M104+M106+M108+M110+M112+M114+M116+M118+M120+M122+M124+M126+M128+M130+M132+M134+M136+M138+M140+M142+M144 -> 375.04
B39: -3 | C39: BC-02 | D39: 7.67 | F39: 1 | G39: EV-33 | H39: 12.5 | I39: USO Y GOCE EXCLUSIVO | K39: 1 | L39: B-019 | M39: =4.79-0.34 -> 4.45 | N39: BODEGA
B40: -3 | C40: BC-03 | D40: 7.6 | F40: 1 | G40: EV-34 | H40: 12.5 | I40: USO Y GOCE EXCLUSIVO | L40: E-46 | M40: 13.63 | N40: ESTACIONAMIENTO | P40: TOTAL EST SUB2 | R40: =SUM(R37:R38) -> 988.66
B41: -3 | C41: BC-04 | D41: 7.63 | F41: 1 | G41: EV-35 | H41: 12.5 | I41: USO Y GOCE EXCLUSIVO | K41: 1 | L41: B-020 | M41: =4.77-0.19 -> 4.58 | N41: BODEGA
B42: -3 | C42: BC-05 | D42: 7.63 | F42: 1 | G42: EV-36 | H42: 12.5 | I42: USO Y GOCE EXCLUSIVO | L42: E-47 | M42: 13.46 | N42: ESTACIONAMIENTO
...

Sheet INFO CONCON
O80: sumatorio longuitudes en metros de las curvas | P80: =20.53+38.68+59.03+79.05+97.7+104.07+135.54+136.84+140.61+142.34+194.98+168.58+138.41+113.51+115.26+112.05+104.84+104+102.86+101.67+89.93+87.87+85.79+83.91+82.58+81.38+80.15+78.65+76.21+82.2+24.93+53.64+15.21+51.32 -> 3184.32
O83: s=(IxLx100)/A | P83: =(0.5*P80*100)/5312 -> 29.972892

Sheet INFO COMERCIAL
T23: 237.32
T24: 277.59
T25: 0
T32: =SUM(T23:T31) -> 514.91
R35: 1 por cada 50m2 | T35: =T32/50 -> 10.2982 | U35: =T35 -> 10.2982
R37: 1 por cada 100m2 | T37: =T32/100 -> 5.1491 | U37: =T37 -> 5.1491

Sheet Evaluación V0
B2: Superficie terreno | D2: 5312 | E2: m2 | G2: PROPUESTA
B3: Area Afecta a Utilidad Publica | D3: 0 | E3: m2 | G3: N° de Pisos | H3: 22
B4: Superficie Neta | D4: 5312 | E4: m2 | G4: Altura piso 1° | H4: 2.52
B5: Constructibilidad max permitida | D5: 13811.2 | E5: m2 | G5: Altura piso tipo | H5: 2.52
B6: Superficie Media Calzada | D6: 2657.02 | E6: m2 | G6: Altura Subterraneo 1 | H6: 2.88
B7: Superficie para Densidad | D7: 7969.02 | E7: m2 | G7: Altura Subterraneo 2
B8: Numero de vivendas permitidas | D8: 195.24099 | E8: un | G8: Altura Subterraneo 3 | H8: -
B9: Media departamentos | D9: 70.739244 | E9: m2 | G9: Altura npt 1° Nivel acceso | H9: 0.15
G10: Altura total Edificio | H10: 55.44
G11: Altura a enterrarse | H11: 1.44
B12: Costos | G12: Altura total sobre N.T.N. | H12: 55
B14: Superficie total a construir | C14: 12346.83 | D14: m2
B15: Costo Construcció | C15: 22 | D15: UF | G15: Ingresos
B16: Total Construcción | C16: =C14*C15 -> 271630.26 | D16: UF | E16: Neto
G17: DEPTO-A | H17: DEPTO-B | I17: DEPTO-C1 | J17: DEPTO-C2 | K17: DEPTO-D | L17: DEPTO-E | M17: DEPTO-F
B18: Evaluación y Estudios | C18: 10000 | D18: UF | E18: Neto | G18: 38 | H18: 40 | I18: 19 | J18: 20 | K18: 39 | L18: 19 | M18: 20
G19: 1D+1B+K | H19: 2D+2B+K | I19: 2D+2B+K (MARIPOSA) | J19: 2D+2B+K (MARIPOSA) | K19: 2D+2B+K | L19: 3D+2B+K | M19: 2D+2B+K
B20: Comercialización | C20: 8000 | D20: UF | E20: Neto | G20: 33.24 | H20: 50.18 | I20: 50.18 | J20: 50.28 | K20: 57.67 | L20: 71.18 | M20: 60.68
G21: 2500 | H21: 4100 | I21: 4500 | J21: 4700 | K21: 5000 | L21: 6000 | M21: 5100
B22: Imprevistos | C22: 10000 | D22: UF | E22: Neto | G22: =G18*G21 -> 95000 | H22: =H18*H21 -> 164000 | I22: =I18*I21 -> 85500 | J22: =J18*J21 -> 94000 | K22: =K18*K21 -> 195000 | L22: =L18*L21 -> 114000 | M22: =M18*M21 -> 102000
B24: Total | C24: =C16+C18+C20+C22 -> 299630.26 | G24: Total Ingresos | H24: =G22+H22+I22+J22+K22+L22+M22 -> 849500
B26: Terreno | C26: 5312 | G26: Margen | H26: =H24-C30 -> 406445.74
B27: Valor Terreno | C27: 27
B28: Total Terreno | C28: =C26*C27 -> 143424
B30: Total Proyecto | C30: =C24+C28 -> 443054.26
